<?xml version="1.0" ?>
<!-- =================================================================================== -->
<!-- |    This document was autogenerated by xacro from /home/zychen/dev_ws/install/task2/share/task2/urdf/trans_robot_ns1.urdf.xacro | -->
<!-- |    EDITING THIS FILE BY HAND IS NOT RECOMMENDED                                 | -->
<!-- =================================================================================== -->
<robot name="robot1">
  <!-- 添加虚拟部件 -->
  <link name="robot1_base_footprint">
        </link>
  <!-- 机器人身体部分 -->
  <link name="robot1_base_link">
    <!-- 部件外观描述 -->
    <visual>
      <!-- 沿自己几何中心的偏移与旋转量 -->
      <origin rpy="0 0 0" xyz="0 0 0"/>
      <!-- 几何形状 -->
      <geometry>
        <!-- 圆柱体，半径0.1m，高度 0.12m 在这里把参数用上 -->
        <cylinder length="0.12" radius="0.1"/>
      </geometry>
      <!-- 材质子标签-蓝色 -->
      <material name="blue">
        <color rgba="0.1 0.1 1.0 0.5"/>
      </material>
    </visual>
    <!-- 添加碰撞属性,可以和visual相同 -->
    <collision>
      <!-- 沿自己几何中心的偏移与旋转量 -->
      <origin rpy="0 0 0" xyz="0 0 0"/>
      <!-- 几何形状 -->
      <geometry>
        <!-- 圆柱体，半径0.1m，高度 0.12m 在这里把参数用上 -->
        <cylinder length="0.12" radius="0.1"/>
      </geometry>
      <!-- 材质子标签-蓝色 -->
      <material name="blue">
        <color rgba="0.1 0.1 1.0 0.5"/>
      </material>
    </collision>
    <inertial>
      <mass value="1.0"/>
      <inertia ixx="0.0037000000000000006" ixy="0" ixz="0" iyy="0.0037000000000000006" iyz="0" izz="0.005000000000000001"/>
    </inertial>
  </link>
  <!-- 机器人关节 -->
  <joint name="robot1_joint_name" type="fixed">
    <!-- 父部件 -->
    <parent link="robot1_base_footprint"/>
    <!-- 子部件 -->
    <child link="robot1_base_link"/>
    <!-- 这里最好设置成一个可变的值 -->
    <origin rpy="0.0 0.0 0.0" xyz="0.0 0.0 0.091"/>
  </joint>
  <gazebo reference="robot1_base_link">
    <material>Gazebo/Black</material>
  </gazebo>
  <!-- 机器人IMU部件 -->
  <link name="robot1_imu_link">
    <visual>
      <origin rpy="0 0 0" xyz="0 0 0"/>
      <geometry>
        <box size="0.02 0.02 0.02"/>
      </geometry>
      <material name="black">
        <color rgba="0 0 0 0.5"/>
      </material>
    </visual>
    <collision>
      <origin rpy="0 0 0" xyz="0 0 0"/>
      <geometry>
        <box size="0.02 0.02 0.02"/>
      </geometry>
      <material name="black">
        <color rgba="0 0 0 0.5"/>
      </material>
    </collision>
    <inertial>
      <mass value="0.05"/>
      <inertia ixx="3.3333333333333333e-06" ixy="0.0" ixz="0.0" iyy="3.3333333333333333e-06" iyz="0.0" izz="3.3333333333333333e-06"/>
    </inertial>
  </link>
  <!-- 机器人关节 -->
  <joint name="robot1_imu_joint" type="fixed">
    <!-- 父部件 -->
    <parent link="robot1_base_link"/>
    <!-- 子部件 -->
    <child link="robot1_imu_link"/>
    <!-- 子部件相对父部件的平移和旋转 -->
    <origin rpy="0 0 0" xyz="0 0 0.02"/>
  </joint>
  <!-- 虚拟模块 -->
  <link name="robot1_camera_optical_link"/>
  <!-- 机器人 IMU 部件 -->
  <link name="robot1_camera_link">
    <visual>
      <origin rpy="0 0 0" xyz="0 0 0"/>
      <geometry>
        <box size="0.02 0.1 0.02"/>
      </geometry>
      <material name="g">
        <color rgba="0 1 0 0.5"/>
      </material>
    </visual>
    <collision>
      <origin rpy="0 0 0" xyz="0 0 0"/>
      <geometry>
        <box size="0.02 0.1 0.02"/>
      </geometry>
      <material name="g">
        <color rgba="0 1 0 0.5"/>
      </material>
    </collision>
    <inertial>
      <mass value="0.1"/>
      <inertia ixx="8.666666666666668e-05" ixy="0.0" ixz="0.0" iyy="6.666666666666667e-06" iyz="0.0" izz="8.666666666666668e-05"/>
    </inertial>
  </link>
  <!-- 机器人关节 -->
  <joint name="robot1_camera_joint" type="fixed">
    <!-- 父部件 -->
    <parent link="robot1_base_link"/>
    <!-- 子部件 -->
    <child link="robot1_camera_link"/>
    <!-- 子部件相对父部件的平移和旋转 -->
    <origin rpy="0 0 0" xyz="0.1 0 0.075"/>
  </joint>
  <!-- 把相机 z 轴朝向前方 -->
  <joint name="robot1_camera_optical_link_joint" type="fixed">
    <parent link="robot1_camera_link"/>
    <child link="robot1_camera_optical_link"/>
    <origin rpy="-1.5707963267948966 0.0 -1.5707963267948966" xyz="0 0 0"/>
  </joint>
  <!-- Gazebo 配置 -->
  <gazebo reference="robot1_camera_link">
    <material>Gazebo/Yellow</material>
  </gazebo>
  <!-- 雷达支撑杆 -->
  <link name="robot1_laser_cylinder_link">
    <visual>
      <origin rpy="0 0 0" xyz="0 0 0"/>
      <geometry>
        <cylinder length="0.10" radius="0.01"/>
      </geometry>
      <material name="r">
        <color rgba="1 0 0 1.0"/>
      </material>
    </visual>
    <collision>
      <origin rpy="0 0 0" xyz="0 0 0"/>
      <geometry>
        <cylinder length="0.10" radius="0.01"/>
      </geometry>
      <material name="r">
        <color rgba="1 0 0 1.0"/>
      </material>
    </collision>
    <inertial>
      <mass value="0.05"/>
      <inertia ixx="4.2916666666666675e-05" ixy="0" ixz="0" iyy="4.2916666666666675e-05" iyz="0" izz="2.5e-06"/>
    </inertial>
  </link>
  <!-- 雷达 -->
  <link name="robot1_laser_link">
    <visual>
      <origin rpy="0 0 0" xyz="0 0 0"/>
      <geometry>
        <cylinder length="0.02" radius="0.02"/>
      </geometry>
      <material name="r">
        <color rgba="1 0 0 1.0"/>
      </material>
    </visual>
    <collision>
      <origin rpy="0 0 0" xyz="0 0 0"/>
      <geometry>
        <cylinder length="0.02" radius="0.02"/>
      </geometry>
      <material name="r">
        <color rgba="1 0 0 1.0"/>
      </material>
    </collision>
    <inertial>
      <mass value="0.1"/>
      <inertia ixx="1.3333333333333332e-05" ixy="0" ixz="0" iyy="1.3333333333333332e-05" iyz="0" izz="2e-05"/>
    </inertial>
  </link>
  <!-- 将雷达固定到支撑杆 -->
  <joint name="robot1_laser_joint" type="fixed">
    <!-- 父部件 -->
    <parent link="robot1_laser_cylinder_link"/>
    <!-- 子部件 -->
    <child link="robot1_laser_link"/>
    <!-- 子部件相对父部件的平移和旋转 -->
    <origin rpy="0 0 0" xyz="0 0 0.05"/>
  </joint>
  <joint name="robot1_laser_cylinder_joint" type="fixed">
    <!-- 父部件 -->
    <parent link="robot1_base_link"/>
    <!-- 子部件 -->
    <child link="robot1_laser_cylinder_link"/>
    <!-- 子部件相对父部件的平移和旋转 -->
    <origin rpy="0 0 0" xyz="0.0 0 0.1"/>
  </joint>
  <gazebo reference="robot1_laser_cylinder_link">
    <material>Gazebo/Red</material>
  </gazebo>
  <gazebo reference="robot1_laser_link">
    <material>Gazebo/Red</material>
  </gazebo>
  <!-- 机器人IMU部件 -->
  <link name="robot1/left_wheel_link">
    <visual>
      <!-- 需要反转圆柱体90度 -->
      <origin rpy="1.57079 0 0" xyz="0 0 0"/>
      <geometry>
        <cylinder length="0.04" radius="0.032"/>
      </geometry>
      <material name="yellow">
        <color rgba="1 1 0 0.8"/>
      </material>
    </visual>
    <collision>
      <!-- 需要反转圆柱体90度 -->
      <origin rpy="1.57079 0 0" xyz="0 0 0"/>
      <geometry>
        <cylinder length="0.04" radius="0.032"/>
      </geometry>
      <material name="yellow">
        <color rgba="1 1 0 0.8"/>
      </material>
    </collision>
    <inertial>
      <mass value="0.05"/>
      <inertia ixx="1.9466666666666668e-05" ixy="0" ixz="0" iyy="1.9466666666666668e-05" iyz="0" izz="2.56e-05"/>
    </inertial>
  </link>
  <!-- 机器人关节 类型要设置为continuous 可转动的-->
  <joint name="robot1/left_wheel_joint" type="continuous">
    <!-- 父部件 -->
    <parent link="robot1_base_link"/>
    <!-- 子部件 -->
    <child link="robot1/left_wheel_link"/>
    <!-- 子部件相对父部件的平移和旋转 -->
    <origin rpy="0 0 0" xyz="0.0 0.1 -0.06"/>
    <!-- 表示绕Y轴旋转 -->
    <axis xyz="0.0 1 0.0"/>
  </joint>
  <gazebo reference="robot1/left_wheel_link">
    <!--  https://www.bilibili.com/video/BV1k8mNYyEjW/?spm_id_from=333.788.videopod.sections&vd_source=6aef8a8b18d581883e4331f31b8d68f0 这里提高了摩檫力的配置-->
    <mu1 value="20.0"/>
    <mu2 value="20.0"/>
    <kp value="1000000000.0"/>
    <kd value="1.0"/>
    <material>Gazebo/Blue</material>
  </gazebo>
  <!-- 机器人IMU部件 -->
  <link name="robot1/right_wheel_link">
    <visual>
      <!-- 需要反转圆柱体90度 -->
      <origin rpy="1.57079 0 0" xyz="0 0 0"/>
      <geometry>
        <cylinder length="0.04" radius="0.032"/>
      </geometry>
      <material name="yellow">
        <color rgba="1 1 0 0.8"/>
      </material>
    </visual>
    <collision>
      <!-- 需要反转圆柱体90度 -->
      <origin rpy="1.57079 0 0" xyz="0 0 0"/>
      <geometry>
        <cylinder length="0.04" radius="0.032"/>
      </geometry>
      <material name="yellow">
        <color rgba="1 1 0 0.8"/>
      </material>
    </collision>
    <inertial>
      <mass value="0.05"/>
      <inertia ixx="1.9466666666666668e-05" ixy="0" ixz="0" iyy="1.9466666666666668e-05" iyz="0" izz="2.56e-05"/>
    </inertial>
  </link>
  <!-- 机器人关节 类型要设置为continuous 可转动的-->
  <joint name="robot1/right_wheel_joint" type="continuous">
    <!-- 父部件 -->
    <parent link="robot1_base_link"/>
    <!-- 子部件 -->
    <child link="robot1/right_wheel_link"/>
    <!-- 子部件相对父部件的平移和旋转 -->
    <origin rpy="0 0 0" xyz="0.0 -0.1 -0.06"/>
    <!-- 表示绕Y轴旋转 -->
    <axis xyz="0.0 1 0.0"/>
  </joint>
  <gazebo reference="robot1/right_wheel_link">
    <!--  https://www.bilibili.com/video/BV1k8mNYyEjW/?spm_id_from=333.788.videopod.sections&vd_source=6aef8a8b18d581883e4331f31b8d68f0 这里提高了摩檫力的配置-->
    <mu1 value="20.0"/>
    <mu2 value="20.0"/>
    <kp value="1000000000.0"/>
    <kd value="1.0"/>
    <material>Gazebo/Blue</material>
  </gazebo>
  <!-- 机器人IMU部件 -->
  <link name="robot1/front_wheel_link">
    <visual>
      <!-- 需要反转圆柱体90度 -->
      <origin rpy="1.57079 0 0" xyz="0 0 0"/>
      <geometry>
        <!-- 万向轮形状应该为球体 -->
        <sphere radius="0.016"/>
      </geometry>
      <material name="yellow">
        <color rgba="1 1 0 0.8"/>
      </material>
    </visual>
    <collision>
      <!-- 需要反转圆柱体90度 -->
      <origin rpy="1.57079 0 0" xyz="0 0 0"/>
      <geometry>
        <!-- 万向轮形状应该为球体 -->
        <sphere radius="0.016"/>
      </geometry>
      <material name="yellow">
        <color rgba="1 1 0 0.8"/>
      </material>
    </collision>
    <inertial>
      <mass value="0.05"/>
      <inertia ixx="5.120000000000001e-06" ixy="0.0" ixz="0.0" iyy="5.120000000000001e-06" iyz="0.0" izz="5.120000000000001e-06"/>
    </inertial>
  </link>
  <!-- 万向轮设置为固定,实际上应该是可动的,我们后续仿真进行操作-->
  <joint name="robot1/front_wheel_joint" type="fixed">
    <!-- 父部件 -->
    <parent link="robot1_base_link"/>
    <!-- 子部件 -->
    <child link="robot1/front_wheel_link"/>
    <!-- 子部件相对父部件的平移和旋转 -->
    <origin rpy="0 0 0" xyz="0.08 0 -0.076"/>
  </joint>
  <gazebo reference="robot1/front_wheel_link">
    <!--  https://www.bilibili.com/video/BV1k8mNYyEjW/?spm_id_from=333.788.videopod.sections&vd_source=6aef8a8b18d581883e4331f31b8d68f0 这里摩檫力为0的配置-->
    <mu1 value="0.0"/>
    <mu2 value="0.0"/>
    <kp value="1000000000.0"/>
    <kd value="1.0"/>
    <material>Gazebo/Blue</material>
  </gazebo>
  <!-- 机器人IMU部件 -->
  <link name="robot1/back_wheel_link">
    <visual>
      <!-- 需要反转圆柱体90度 -->
      <origin rpy="1.57079 0 0" xyz="0 0 0"/>
      <geometry>
        <!-- 万向轮形状应该为球体 -->
        <sphere radius="0.016"/>
      </geometry>
      <material name="yellow">
        <color rgba="1 1 0 0.8"/>
      </material>
    </visual>
    <collision>
      <!-- 需要反转圆柱体90度 -->
      <origin rpy="1.57079 0 0" xyz="0 0 0"/>
      <geometry>
        <!-- 万向轮形状应该为球体 -->
        <sphere radius="0.016"/>
      </geometry>
      <material name="yellow">
        <color rgba="1 1 0 0.8"/>
      </material>
    </collision>
    <inertial>
      <mass value="0.05"/>
      <inertia ixx="5.120000000000001e-06" ixy="0.0" ixz="0.0" iyy="5.120000000000001e-06" iyz="0.0" izz="5.120000000000001e-06"/>
    </inertial>
  </link>
  <!-- 万向轮设置为固定,实际上应该是可动的,我们后续仿真进行操作-->
  <joint name="robot1/back_wheel_joint" type="fixed">
    <!-- 父部件 -->
    <parent link="robot1_base_link"/>
    <!-- 子部件 -->
    <child link="robot1/back_wheel_link"/>
    <!-- 子部件相对父部件的平移和旋转 -->
    <origin rpy="0 0 0" xyz="-0.08 0 -0.076"/>
  </joint>
  <gazebo reference="robot1/back_wheel_link">
    <!--  https://www.bilibili.com/video/BV1k8mNYyEjW/?spm_id_from=333.788.videopod.sections&vd_source=6aef8a8b18d581883e4331f31b8d68f0 这里摩檫力为0的配置-->
    <mu1 value="0.0"/>
    <mu2 value="0.0"/>
    <kp value="1000000000.0"/>
    <kd value="1.0"/>
    <material>Gazebo/Blue</material>
  </gazebo>
  <gazebo>
    <plugin filename="libgazebo_ros_diff_drive.so" name="diff_drive">
      <ros>
        <!-- 使用传入的命名空间 -->
        <namespace>robot1</namespace>
        <remapping>cmd_vel:=robot1/cmd_vel</remapping>
        <remapping>odom:=robot1/odom</remapping>
      </ros>
      <!-- 更新的频率 -->
      <update_rate>30</update_rate>
      <!-- wheels 两轮差速模型 -->
      <left_joint>robot1/left_wheel_joint</left_joint>
      <right_joint>robot1/right_wheel_joint</right_joint>
      <!-- kinematics 需要知道轮子的距离和直径 -->
      <wheel_separation>0.2</wheel_separation>
      <wheel_diameter>0.064</wheel_diameter>
      <!-- limits -->
      <max_wheel_torque>20</max_wheel_torque>
      <max_wheel_acceleration>1.0</max_wheel_acceleration>
      <!-- output -->
      <publish_odom>true</publish_odom>
      <publish_odom_tf>true</publish_odom_tf>
      <publish_wheel_tf>true</publish_wheel_tf>
      <odometry_frame>robot1/odom</odometry_frame>
      <!-- 注意我们使用base_footprint作为父节点 -->
      <robot_base_frame>robot1/base_footprint</robot_base_frame>
    </plugin>
  </gazebo>
  <!-- 激光传感器 -->
  <gazebo reference="laser_link">
    <sensor name="robot1_laserscan" type="ray">
      <plugin filename="libgazebo_ros_ray_sensor.so" name="robot1_laserscan_plugin">
        <ros>
          <namespace>robot1</namespace>
          <remapping>~/out:=robot1/scan</remapping>
        </ros>
        <output_type>sensor_msgs/LaserScan</output_type>
        <frame_name>robot1/laser_link</frame_name>
      </plugin>
      <always_on>true</always_on>
      <visualize>true</visualize>
      <update_rate>5</update_rate>
      <pose>0 0 0 0 0 0</pose>
      <ray>
        <scan>
          <horizontal>
            <samples>360</samples>
            <resolution>1.000000</resolution>
            <min_angle>0.000000</min_angle>
            <max_angle>6.280000</max_angle>
          </horizontal>
        </scan>
        <range>
          <min>0.120000</min>
          <max>8.0</max>
          <resolution>0.015000</resolution>
        </range>
        <noise>
          <type>gaussian</type>
          <mean>0.0</mean>
          <stddev>0.01</stddev>
        </noise>
      </ray>
    </sensor>
  </gazebo>
  <!-- IMU 传感器 -->
  <gazebo reference="imu_link">
    <sensor name="robot1_imu_sensor" type="imu">
      <plugin filename="libgazebo_ros_imu_sensor.so" name="robot1_imu_plugin">
        <ros>
          <namespace>robot1</namespace>
          <remapping>~/out:=robot1/imu</remapping>
        </ros>
        <initial_orientation_as_reference>false</initial_orientation_as_reference>
      </plugin>
      <update_rate>100</update_rate>
      <always_on>true</always_on>
      <imu>
        <angular_velocity>
          <x>
            <noise type="gaussian">
              <mean>0.0</mean>
              <stddev>2e-4</stddev>
              <bias_mean>0.0000075</bias_mean>
              <bias_stddev>0.0000008</bias_stddev>
            </noise>
          </x>
          <y>
            <noise type="gaussian">
              <mean>0.0</mean>
              <stddev>2e-4</stddev>
              <bias_mean>0.0000075</bias_mean>
              <bias_stddev>0.0000008</bias_stddev>
            </noise>
          </y>
          <z>
            <noise type="gaussian">
              <mean>0.0</mean>
              <stddev>2e-4</stddev>
              <bias_mean>0.0000075</bias_mean>
              <bias_stddev>0.0000008</bias_stddev>
            </noise>
          </z>
        </angular_velocity>
        <linear_acceleration>
          <x>
            <noise type="gaussian">
              <mean>0.0</mean>
              <stddev>1.7e-2</stddev>
              <bias_mean>0.1</bias_mean>
              <bias_stddev>0.001</bias_stddev>
            </noise>
          </x>
          <y>
            <noise type="gaussian">
              <mean>0.0</mean>
              <stddev>1.7e-2</stddev>
              <bias_mean>0.1</bias_mean>
              <bias_stddev>0.001</bias_stddev>
            </noise>
          </y>
          <z>
            <noise type="gaussian">
              <mean>0.0</mean>
              <stddev>1.7e-2</stddev>
              <bias_mean>0.1</bias_mean>
              <bias_stddev>0.001</bias_stddev>
            </noise>
          </z>
        </linear_acceleration>
      </imu>
    </sensor>
  </gazebo>
  <!-- 深度相机 -->
  <gazebo reference="camera_link">
    <sensor name="robot1_camera_sensor" type="depth">
      <plugin filename="libgazebo_ros_camera.so" name="robot1_depth_camera">
        <ros>
          <namespace>robot1</namespace>
        </ros>
        <frame_name>robot1/camera_optical_link</frame_name>
      </plugin>
      <always_on>true</always_on>
      <update_rate>10</update_rate>
      <camera name="camera">
        <horizontal_fov>1.5009831567</horizontal_fov>
        <image>
          <width>800</width>
          <height>600</height>
          <format>R8G8B8</format>
        </image>
        <distortion>
          <k1>0.0</k1>
          <k2>0.0</k2>
          <k3>0.0</k3>
          <p1>0.0</p1>
          <p2>0.0</p2>
          <center>0.5 0.5</center>
        </distortion>
      </camera>
    </sensor>
  </gazebo>
</robot>