<?xml version="1.0"?>
<robot xmlns:xacro="http://www.ros.org/wiki/xacro">
    <xacro:include filename="$(find task2)/urdf/common_inertia.xacro"/>
    <!-- 声明wheel模块 轮子需要复用-->
    <xacro:macro name="wheel_xacro" params="whlee_name xyz">
        <!-- 机器人IMU部件 -->
        <link name="${whlee_name}_link">
            <visual>
                <!-- 需要反转圆柱体90度 -->
                <origin xyz="0 0 0" rpy="1.57079 0 0" />
                <geometry>
                    <cylinder radius="0.032" length="0.04"/>
                </geometry>
                <material name="yellow">
                    <color rgba="1 1 0 0.8" />
                </material>
            </visual>
            <collision>
                <!-- 需要反转圆柱体90度 -->
                <origin xyz="0 0 0" rpy="1.57079 0 0" />
                <geometry>
                    <cylinder radius="0.032" length="0.04"/>
                </geometry>
                <material name="yellow">
                    <color rgba="1 1 0 0.8" />
                </material>
            </collision>
            <xacro:cylinder_inertia m="0.05" r="0.032" h="0.04"/>
        </link>

        <!-- 机器人关节 类型要设置为continuous 可转动的-->
        <joint name="${whlee_name}_joint" type="continuous">
            <!-- 父部件 -->
            <parent link="base_link" />
            <!-- 子部件 -->
            <child link="${whlee_name}_link" />
            <!-- 子部件相对父部件的平移和旋转 -->
            <origin xyz="${xyz}" rpy="0 0 0" />
            <!-- 表示绕Y轴旋转 -->
            <axis xyz="0.0 1 0.0"/>
        </joint>
        <gazebo reference="${whlee_name}_link">
        <!--  https://www.bilibili.com/video/BV1k8mNYyEjW/?spm_id_from=333.788.videopod.sections&vd_source=6aef8a8b18d581883e4331f31b8d68f0 这里提高了摩檫力的配置-->
            <mu1 value="20.0" />
            <mu2 value="20.0" />
            <kp value="1000000000.0" />
            <kd value="1.0" />
            <material>Gazebo/Blue</material>
        </gazebo>
    </xacro:macro>

</robot>